Exception on / [POST]
Traceback (most recent call last):
  File "/home/ubuntu/.local/lib/python3.6/site-packages/flask/app.py", line 2447, in wsgi_app
    response = self.full_dispatch_request()
  File "/home/ubuntu/.local/lib/python3.6/site-packages/flask/app.py", line 1952, in full_dispatch_request
    rv = self.handle_user_exception(e)
  File "/home/ubuntu/.local/lib/python3.6/site-packages/flask/app.py", line 1821, in handle_user_exception
    reraise(exc_type, exc_value, tb)
  File "/home/ubuntu/.local/lib/python3.6/site-packages/flask/_compat.py", line 39, in reraise
    raise value
  File "/home/ubuntu/.local/lib/python3.6/site-packages/flask/app.py", line 1950, in full_dispatch_request
    rv = self.dispatch_request()
  File "/home/ubuntu/.local/lib/python3.6/site-packages/flask/app.py", line 1936, in dispatch_request
    return self.view_functions[rule.endpoint](**req.view_args)
  File "/home/ubuntu/flask_gunicorn_nginx_docker/flask_app/app.py", line 117, in func
    urls = list(data["urls"])
KeyError: 'urls'
Exception on / [POST]
Traceback (most recent call last):
  File "/home/ubuntu/.local/lib/python3.6/site-packages/flask/app.py", line 2447, in wsgi_app
    response = self.full_dispatch_request()
  File "/home/ubuntu/.local/lib/python3.6/site-packages/flask/app.py", line 1952, in full_dispatch_request
    rv = self.handle_user_exception(e)
  File "/home/ubuntu/.local/lib/python3.6/site-packages/flask/app.py", line 1821, in handle_user_exception
    reraise(exc_type, exc_value, tb)
  File "/home/ubuntu/.local/lib/python3.6/site-packages/flask/_compat.py", line 39, in reraise
    raise value
  File "/home/ubuntu/.local/lib/python3.6/site-packages/flask/app.py", line 1950, in full_dispatch_request
    rv = self.dispatch_request()
  File "/home/ubuntu/.local/lib/python3.6/site-packages/flask/app.py", line 1936, in dispatch_request
    return self.view_functions[rule.endpoint](**req.view_args)
  File "/home/ubuntu/flask_gunicorn_nginx_docker/flask_app/app.py", line 185, in func
    gary_frame = cv2.cvtColor(roi, cv2.COLOR_RGB2GRAY)
cv2.error: OpenCV(4.2.0) /io/opencv/modules/imgproc/src/color.cpp:182: error: (-215:Assertion failed) !_src.empty() in function 'cvtColor'

Exception on / [POST]
Traceback (most recent call last):
  File "/home/ubuntu/.local/lib/python3.6/site-packages/flask/app.py", line 2447, in wsgi_app
    response = self.full_dispatch_request()
  File "/home/ubuntu/.local/lib/python3.6/site-packages/flask/app.py", line 1952, in full_dispatch_request
    rv = self.handle_user_exception(e)
  File "/home/ubuntu/.local/lib/python3.6/site-packages/flask/app.py", line 1821, in handle_user_exception
    reraise(exc_type, exc_value, tb)
  File "/home/ubuntu/.local/lib/python3.6/site-packages/flask/_compat.py", line 39, in reraise
    raise value
  File "/home/ubuntu/.local/lib/python3.6/site-packages/flask/app.py", line 1950, in full_dispatch_request
    rv = self.dispatch_request()
  File "/home/ubuntu/.local/lib/python3.6/site-packages/flask/app.py", line 1936, in dispatch_request
    return self.view_functions[rule.endpoint](**req.view_args)
  File "/home/ubuntu/flask_gunicorn_nginx_docker/flask_app/app.py", line 185, in func
    gary_frame = cv2.cvtColor(roi, cv2.COLOR_RGB2GRAY)
cv2.error: OpenCV(4.2.0) /io/opencv/modules/imgproc/src/color.cpp:182: error: (-215:Assertion failed) !_src.empty() in function 'cvtColor'

Exception on / [POST]
Traceback (most recent call last):
  File "/home/ubuntu/.local/lib/python3.6/site-packages/flask/app.py", line 2447, in wsgi_app
    response = self.full_dispatch_request()
  File "/home/ubuntu/.local/lib/python3.6/site-packages/flask/app.py", line 1952, in full_dispatch_request
    rv = self.handle_user_exception(e)
  File "/home/ubuntu/.local/lib/python3.6/site-packages/flask/app.py", line 1821, in handle_user_exception
    reraise(exc_type, exc_value, tb)
  File "/home/ubuntu/.local/lib/python3.6/site-packages/flask/_compat.py", line 39, in reraise
    raise value
  File "/home/ubuntu/.local/lib/python3.6/site-packages/flask/app.py", line 1950, in full_dispatch_request
    rv = self.dispatch_request()
  File "/home/ubuntu/.local/lib/python3.6/site-packages/flask/app.py", line 1936, in dispatch_request
    return self.view_functions[rule.endpoint](**req.view_args)
  File "/home/ubuntu/flask_gunicorn_nginx_docker/flask_app/app.py", line 185, in func
    gary_frame = cv2.cvtColor(roi, cv2.COLOR_RGB2GRAY)
cv2.error: OpenCV(4.2.0) /io/opencv/modules/imgproc/src/color.cpp:182: error: (-215:Assertion failed) !_src.empty() in function 'cvtColor'

Exception on / [POST]
Traceback (most recent call last):
  File "/home/ubuntu/.local/lib/python3.6/site-packages/flask/app.py", line 2447, in wsgi_app
    response = self.full_dispatch_request()
  File "/home/ubuntu/.local/lib/python3.6/site-packages/flask/app.py", line 1952, in full_dispatch_request
    rv = self.handle_user_exception(e)
  File "/home/ubuntu/.local/lib/python3.6/site-packages/flask/app.py", line 1821, in handle_user_exception
    reraise(exc_type, exc_value, tb)
  File "/home/ubuntu/.local/lib/python3.6/site-packages/flask/_compat.py", line 39, in reraise
    raise value
  File "/home/ubuntu/.local/lib/python3.6/site-packages/flask/app.py", line 1950, in full_dispatch_request
    rv = self.dispatch_request()
  File "/home/ubuntu/.local/lib/python3.6/site-packages/flask/app.py", line 1936, in dispatch_request
    return self.view_functions[rule.endpoint](**req.view_args)
  File "/home/ubuntu/flask_gunicorn_nginx_docker/flask_app/app.py", line 185, in func
    gary_frame = cv2.cvtColor(roi, cv2.COLOR_RGB2GRAY)
cv2.error: OpenCV(4.2.0) /io/opencv/modules/imgproc/src/color.cpp:182: error: (-215:Assertion failed) !_src.empty() in function 'cvtColor'

Exception on / [POST]
Traceback (most recent call last):
  File "/home/ubuntu/.local/lib/python3.6/site-packages/flask/app.py", line 2447, in wsgi_app
    response = self.full_dispatch_request()
  File "/home/ubuntu/.local/lib/python3.6/site-packages/flask/app.py", line 1952, in full_dispatch_request
    rv = self.handle_user_exception(e)
  File "/home/ubuntu/.local/lib/python3.6/site-packages/flask/app.py", line 1821, in handle_user_exception
    reraise(exc_type, exc_value, tb)
  File "/home/ubuntu/.local/lib/python3.6/site-packages/flask/_compat.py", line 39, in reraise
    raise value
  File "/home/ubuntu/.local/lib/python3.6/site-packages/flask/app.py", line 1950, in full_dispatch_request
    rv = self.dispatch_request()
  File "/home/ubuntu/.local/lib/python3.6/site-packages/flask/app.py", line 1936, in dispatch_request
    return self.view_functions[rule.endpoint](**req.view_args)
  File "/home/ubuntu/flask_gunicorn_nginx_docker/flask_app/app.py", line 185, in func
    gary_frame = cv2.cvtColor(roi, cv2.COLOR_RGB2GRAY)
cv2.error: OpenCV(4.2.0) /io/opencv/modules/imgproc/src/color.cpp:182: error: (-215:Assertion failed) !_src.empty() in function 'cvtColor'

Exception on / [POST]
Traceback (most recent call last):
  File "/home/ubuntu/.local/lib/python3.6/site-packages/flask/app.py", line 2447, in wsgi_app
    response = self.full_dispatch_request()
  File "/home/ubuntu/.local/lib/python3.6/site-packages/flask/app.py", line 1952, in full_dispatch_request
    rv = self.handle_user_exception(e)
  File "/home/ubuntu/.local/lib/python3.6/site-packages/flask/app.py", line 1821, in handle_user_exception
    reraise(exc_type, exc_value, tb)
  File "/home/ubuntu/.local/lib/python3.6/site-packages/flask/_compat.py", line 39, in reraise
    raise value
  File "/home/ubuntu/.local/lib/python3.6/site-packages/flask/app.py", line 1950, in full_dispatch_request
    rv = self.dispatch_request()
  File "/home/ubuntu/.local/lib/python3.6/site-packages/flask/app.py", line 1936, in dispatch_request
    return self.view_functions[rule.endpoint](**req.view_args)
  File "/home/ubuntu/flask_gunicorn_nginx_docker/flask_app/app.py", line 185, in func
    gary_frame = cv2.cvtColor(roi, cv2.COLOR_RGB2GRAY)
cv2.error: OpenCV(4.2.0) /io/opencv/modules/imgproc/src/color.cpp:182: error: (-215:Assertion failed) !_src.empty() in function 'cvtColor'

Exception on / [POST]
Traceback (most recent call last):
  File "/home/ubuntu/.local/lib/python3.6/site-packages/flask/app.py", line 2447, in wsgi_app
    response = self.full_dispatch_request()
  File "/home/ubuntu/.local/lib/python3.6/site-packages/flask/app.py", line 1952, in full_dispatch_request
    rv = self.handle_user_exception(e)
  File "/home/ubuntu/.local/lib/python3.6/site-packages/flask/app.py", line 1821, in handle_user_exception
    reraise(exc_type, exc_value, tb)
  File "/home/ubuntu/.local/lib/python3.6/site-packages/flask/_compat.py", line 39, in reraise
    raise value
  File "/home/ubuntu/.local/lib/python3.6/site-packages/flask/app.py", line 1950, in full_dispatch_request
    rv = self.dispatch_request()
  File "/home/ubuntu/.local/lib/python3.6/site-packages/flask/app.py", line 1936, in dispatch_request
    return self.view_functions[rule.endpoint](**req.view_args)
  File "/home/ubuntu/flask_gunicorn_nginx_docker/flask_app/app.py", line 185, in func
    gary_frame = cv2.cvtColor(roi, cv2.COLOR_RGB2GRAY)
cv2.error: OpenCV(4.2.0) /io/opencv/modules/imgproc/src/color.cpp:182: error: (-215:Assertion failed) !_src.empty() in function 'cvtColor'

Exception on / [POST]
Traceback (most recent call last):
  File "/home/ubuntu/.local/lib/python3.6/site-packages/flask/app.py", line 2447, in wsgi_app
    response = self.full_dispatch_request()
  File "/home/ubuntu/.local/lib/python3.6/site-packages/flask/app.py", line 1952, in full_dispatch_request
    rv = self.handle_user_exception(e)
  File "/home/ubuntu/.local/lib/python3.6/site-packages/flask/app.py", line 1821, in handle_user_exception
    reraise(exc_type, exc_value, tb)
  File "/home/ubuntu/.local/lib/python3.6/site-packages/flask/_compat.py", line 39, in reraise
    raise value
  File "/home/ubuntu/.local/lib/python3.6/site-packages/flask/app.py", line 1950, in full_dispatch_request
    rv = self.dispatch_request()
  File "/home/ubuntu/.local/lib/python3.6/site-packages/flask/app.py", line 1936, in dispatch_request
    return self.view_functions[rule.endpoint](**req.view_args)
  File "/home/ubuntu/flask_gunicorn_nginx_docker/flask_app/app.py", line 185, in func
    gary_frame = cv2.cvtColor(roi, cv2.COLOR_RGB2GRAY)
cv2.error: OpenCV(4.2.0) /io/opencv/modules/imgproc/src/color.cpp:182: error: (-215:Assertion failed) !_src.empty() in function 'cvtColor'

Exception on / [POST]
Traceback (most recent call last):
  File "/home/ubuntu/.local/lib/python3.6/site-packages/flask/app.py", line 2447, in wsgi_app
    response = self.full_dispatch_request()
  File "/home/ubuntu/.local/lib/python3.6/site-packages/flask/app.py", line 1952, in full_dispatch_request
    rv = self.handle_user_exception(e)
  File "/home/ubuntu/.local/lib/python3.6/site-packages/flask/app.py", line 1821, in handle_user_exception
    reraise(exc_type, exc_value, tb)
  File "/home/ubuntu/.local/lib/python3.6/site-packages/flask/_compat.py", line 39, in reraise
    raise value
  File "/home/ubuntu/.local/lib/python3.6/site-packages/flask/app.py", line 1950, in full_dispatch_request
    rv = self.dispatch_request()
  File "/home/ubuntu/.local/lib/python3.6/site-packages/flask/app.py", line 1936, in dispatch_request
    return self.view_functions[rule.endpoint](**req.view_args)
  File "/home/ubuntu/flask_gunicorn_nginx_docker/flask_app/app.py", line 185, in func
    gary_frame = cv2.cvtColor(roi, cv2.COLOR_RGB2GRAY)
cv2.error: OpenCV(4.2.0) /io/opencv/modules/imgproc/src/color.cpp:182: error: (-215:Assertion failed) !_src.empty() in function 'cvtColor'

Exception on / [POST]
Traceback (most recent call last):
  File "/home/ubuntu/.local/lib/python3.6/site-packages/flask/app.py", line 2447, in wsgi_app
    response = self.full_dispatch_request()
  File "/home/ubuntu/.local/lib/python3.6/site-packages/flask/app.py", line 1952, in full_dispatch_request
    rv = self.handle_user_exception(e)
  File "/home/ubuntu/.local/lib/python3.6/site-packages/flask/app.py", line 1821, in handle_user_exception
    reraise(exc_type, exc_value, tb)
  File "/home/ubuntu/.local/lib/python3.6/site-packages/flask/_compat.py", line 39, in reraise
    raise value
  File "/home/ubuntu/.local/lib/python3.6/site-packages/flask/app.py", line 1950, in full_dispatch_request
    rv = self.dispatch_request()
  File "/home/ubuntu/.local/lib/python3.6/site-packages/flask/app.py", line 1936, in dispatch_request
    return self.view_functions[rule.endpoint](**req.view_args)
  File "/home/ubuntu/flask_gunicorn_nginx_docker/flask_app/app.py", line 185, in func
    gary_frame = cv2.cvtColor(roi, cv2.COLOR_RGB2GRAY)
cv2.error: OpenCV(4.2.0) /io/opencv/modules/imgproc/src/color.cpp:182: error: (-215:Assertion failed) !_src.empty() in function 'cvtColor'

Exception on / [POST]
Traceback (most recent call last):
  File "/home/ubuntu/.local/lib/python3.6/site-packages/flask/app.py", line 2447, in wsgi_app
    response = self.full_dispatch_request()
  File "/home/ubuntu/.local/lib/python3.6/site-packages/flask/app.py", line 1952, in full_dispatch_request
    rv = self.handle_user_exception(e)
  File "/home/ubuntu/.local/lib/python3.6/site-packages/flask/app.py", line 1821, in handle_user_exception
    reraise(exc_type, exc_value, tb)
  File "/home/ubuntu/.local/lib/python3.6/site-packages/flask/_compat.py", line 39, in reraise
    raise value
  File "/home/ubuntu/.local/lib/python3.6/site-packages/flask/app.py", line 1950, in full_dispatch_request
    rv = self.dispatch_request()
  File "/home/ubuntu/.local/lib/python3.6/site-packages/flask/app.py", line 1936, in dispatch_request
    return self.view_functions[rule.endpoint](**req.view_args)
  File "/home/ubuntu/flask_gunicorn_nginx_docker/flask_app/app.py", line 185, in func
    gary_frame = cv2.cvtColor(roi, cv2.COLOR_RGB2GRAY)
cv2.error: OpenCV(4.2.0) /io/opencv/modules/imgproc/src/color.cpp:182: error: (-215:Assertion failed) !_src.empty() in function 'cvtColor'

Exception on / [POST]
Traceback (most recent call last):
  File "/home/ubuntu/.local/lib/python3.6/site-packages/flask/app.py", line 2447, in wsgi_app
    response = self.full_dispatch_request()
  File "/home/ubuntu/.local/lib/python3.6/site-packages/flask/app.py", line 1952, in full_dispatch_request
    rv = self.handle_user_exception(e)
  File "/home/ubuntu/.local/lib/python3.6/site-packages/flask/app.py", line 1821, in handle_user_exception
    reraise(exc_type, exc_value, tb)
  File "/home/ubuntu/.local/lib/python3.6/site-packages/flask/_compat.py", line 39, in reraise
    raise value
  File "/home/ubuntu/.local/lib/python3.6/site-packages/flask/app.py", line 1950, in full_dispatch_request
    rv = self.dispatch_request()
  File "/home/ubuntu/.local/lib/python3.6/site-packages/flask/app.py", line 1936, in dispatch_request
    return self.view_functions[rule.endpoint](**req.view_args)
  File "/home/ubuntu/flask_gunicorn_nginx_docker/flask_app/app.py", line 185, in func
    gary_frame = cv2.cvtColor(roi, cv2.COLOR_RGB2GRAY)
cv2.error: OpenCV(4.2.0) /io/opencv/modules/imgproc/src/color.cpp:182: error: (-215:Assertion failed) !_src.empty() in function 'cvtColor'

Exception on / [POST]
Traceback (most recent call last):
  File "/home/ubuntu/.local/lib/python3.6/site-packages/flask/app.py", line 2447, in wsgi_app
    response = self.full_dispatch_request()
  File "/home/ubuntu/.local/lib/python3.6/site-packages/flask/app.py", line 1952, in full_dispatch_request
    rv = self.handle_user_exception(e)
  File "/home/ubuntu/.local/lib/python3.6/site-packages/flask/app.py", line 1821, in handle_user_exception
    reraise(exc_type, exc_value, tb)
  File "/home/ubuntu/.local/lib/python3.6/site-packages/flask/_compat.py", line 39, in reraise
    raise value
  File "/home/ubuntu/.local/lib/python3.6/site-packages/flask/app.py", line 1950, in full_dispatch_request
    rv = self.dispatch_request()
  File "/home/ubuntu/.local/lib/python3.6/site-packages/flask/app.py", line 1936, in dispatch_request
    return self.view_functions[rule.endpoint](**req.view_args)
  File "/home/ubuntu/flask_gunicorn_nginx_docker/flask_app/app.py", line 185, in func
    gary_frame = cv2.cvtColor(roi, cv2.COLOR_RGB2GRAY)
cv2.error: OpenCV(4.2.0) /io/opencv/modules/imgproc/src/color.cpp:182: error: (-215:Assertion failed) !_src.empty() in function 'cvtColor'

Exception on / [POST]
Traceback (most recent call last):
  File "/home/ubuntu/.local/lib/python3.6/site-packages/flask/app.py", line 2447, in wsgi_app
    response = self.full_dispatch_request()
  File "/home/ubuntu/.local/lib/python3.6/site-packages/flask/app.py", line 1952, in full_dispatch_request
    rv = self.handle_user_exception(e)
  File "/home/ubuntu/.local/lib/python3.6/site-packages/flask/app.py", line 1821, in handle_user_exception
    reraise(exc_type, exc_value, tb)
  File "/home/ubuntu/.local/lib/python3.6/site-packages/flask/_compat.py", line 39, in reraise
    raise value
  File "/home/ubuntu/.local/lib/python3.6/site-packages/flask/app.py", line 1950, in full_dispatch_request
    rv = self.dispatch_request()
  File "/home/ubuntu/.local/lib/python3.6/site-packages/flask/app.py", line 1936, in dispatch_request
    return self.view_functions[rule.endpoint](**req.view_args)
  File "/home/ubuntu/flask_gunicorn_nginx_docker/flask_app/app.py", line 185, in func
    gary_frame = cv2.cvtColor(roi, cv2.COLOR_RGB2GRAY)
cv2.error: OpenCV(4.2.0) /io/opencv/modules/imgproc/src/color.cpp:182: error: (-215:Assertion failed) !_src.empty() in function 'cvtColor'

Exception on / [POST]
Traceback (most recent call last):
  File "/home/ubuntu/.local/lib/python3.6/site-packages/flask/app.py", line 2447, in wsgi_app
    response = self.full_dispatch_request()
  File "/home/ubuntu/.local/lib/python3.6/site-packages/flask/app.py", line 1952, in full_dispatch_request
    rv = self.handle_user_exception(e)
  File "/home/ubuntu/.local/lib/python3.6/site-packages/flask/app.py", line 1821, in handle_user_exception
    reraise(exc_type, exc_value, tb)
  File "/home/ubuntu/.local/lib/python3.6/site-packages/flask/_compat.py", line 39, in reraise
    raise value
  File "/home/ubuntu/.local/lib/python3.6/site-packages/flask/app.py", line 1950, in full_dispatch_request
    rv = self.dispatch_request()
  File "/home/ubuntu/.local/lib/python3.6/site-packages/flask/app.py", line 1936, in dispatch_request
    return self.view_functions[rule.endpoint](**req.view_args)
  File "/home/ubuntu/flask_gunicorn_nginx_docker/flask_app/app.py", line 185, in func
    gary_frame = cv2.cvtColor(roi, cv2.COLOR_RGB2GRAY)
cv2.error: OpenCV(4.2.0) /io/opencv/modules/imgproc/src/color.cpp:182: error: (-215:Assertion failed) !_src.empty() in function 'cvtColor'

Exception on / [POST]
Traceback (most recent call last):
  File "/home/ubuntu/.local/lib/python3.6/site-packages/flask/app.py", line 2447, in wsgi_app
    response = self.full_dispatch_request()
  File "/home/ubuntu/.local/lib/python3.6/site-packages/flask/app.py", line 1952, in full_dispatch_request
    rv = self.handle_user_exception(e)
  File "/home/ubuntu/.local/lib/python3.6/site-packages/flask/app.py", line 1821, in handle_user_exception
    reraise(exc_type, exc_value, tb)
  File "/home/ubuntu/.local/lib/python3.6/site-packages/flask/_compat.py", line 39, in reraise
    raise value
  File "/home/ubuntu/.local/lib/python3.6/site-packages/flask/app.py", line 1950, in full_dispatch_request
    rv = self.dispatch_request()
  File "/home/ubuntu/.local/lib/python3.6/site-packages/flask/app.py", line 1936, in dispatch_request
    return self.view_functions[rule.endpoint](**req.view_args)
  File "/home/ubuntu/flask_gunicorn_nginx_docker/flask_app/app.py", line 185, in func
    gary_frame = cv2.cvtColor(roi, cv2.COLOR_RGB2GRAY)
cv2.error: OpenCV(4.2.0) /io/opencv/modules/imgproc/src/color.cpp:182: error: (-215:Assertion failed) !_src.empty() in function 'cvtColor'

Exception on / [POST]
Traceback (most recent call last):
  File "/home/ubuntu/.local/lib/python3.6/site-packages/flask/app.py", line 2447, in wsgi_app
    response = self.full_dispatch_request()
  File "/home/ubuntu/.local/lib/python3.6/site-packages/flask/app.py", line 1952, in full_dispatch_request
    rv = self.handle_user_exception(e)
  File "/home/ubuntu/.local/lib/python3.6/site-packages/flask/app.py", line 1821, in handle_user_exception
    reraise(exc_type, exc_value, tb)
  File "/home/ubuntu/.local/lib/python3.6/site-packages/flask/_compat.py", line 39, in reraise
    raise value
  File "/home/ubuntu/.local/lib/python3.6/site-packages/flask/app.py", line 1950, in full_dispatch_request
    rv = self.dispatch_request()
  File "/home/ubuntu/.local/lib/python3.6/site-packages/flask/app.py", line 1936, in dispatch_request
    return self.view_functions[rule.endpoint](**req.view_args)
  File "/home/ubuntu/flask_gunicorn_nginx_docker/flask_app/app.py", line 185, in func
    gary_frame = cv2.cvtColor(roi, cv2.COLOR_RGB2GRAY)
cv2.error: OpenCV(4.2.0) /io/opencv/modules/imgproc/src/color.cpp:182: error: (-215:Assertion failed) !_src.empty() in function 'cvtColor'

Exception on / [POST]
Traceback (most recent call last):
  File "/home/ubuntu/.local/lib/python3.6/site-packages/flask/app.py", line 2447, in wsgi_app
    response = self.full_dispatch_request()
  File "/home/ubuntu/.local/lib/python3.6/site-packages/flask/app.py", line 1952, in full_dispatch_request
    rv = self.handle_user_exception(e)
  File "/home/ubuntu/.local/lib/python3.6/site-packages/flask/app.py", line 1821, in handle_user_exception
    reraise(exc_type, exc_value, tb)
  File "/home/ubuntu/.local/lib/python3.6/site-packages/flask/_compat.py", line 39, in reraise
    raise value
  File "/home/ubuntu/.local/lib/python3.6/site-packages/flask/app.py", line 1950, in full_dispatch_request
    rv = self.dispatch_request()
  File "/home/ubuntu/.local/lib/python3.6/site-packages/flask/app.py", line 1936, in dispatch_request
    return self.view_functions[rule.endpoint](**req.view_args)
  File "/home/ubuntu/flask_gunicorn_nginx_docker/flask_app/app.py", line 185, in func
    gary_frame = cv2.cvtColor(roi, cv2.COLOR_RGB2GRAY)
cv2.error: OpenCV(4.2.0) /io/opencv/modules/imgproc/src/color.cpp:182: error: (-215:Assertion failed) !_src.empty() in function 'cvtColor'

Exception on / [POST]
Traceback (most recent call last):
  File "/home/ubuntu/.local/lib/python3.6/site-packages/flask/app.py", line 2447, in wsgi_app
    response = self.full_dispatch_request()
  File "/home/ubuntu/.local/lib/python3.6/site-packages/flask/app.py", line 1952, in full_dispatch_request
    rv = self.handle_user_exception(e)
  File "/home/ubuntu/.local/lib/python3.6/site-packages/flask/app.py", line 1821, in handle_user_exception
    reraise(exc_type, exc_value, tb)
  File "/home/ubuntu/.local/lib/python3.6/site-packages/flask/_compat.py", line 39, in reraise
    raise value
  File "/home/ubuntu/.local/lib/python3.6/site-packages/flask/app.py", line 1950, in full_dispatch_request
    rv = self.dispatch_request()
  File "/home/ubuntu/.local/lib/python3.6/site-packages/flask/app.py", line 1936, in dispatch_request
    return self.view_functions[rule.endpoint](**req.view_args)
  File "/home/ubuntu/flask_gunicorn_nginx_docker/flask_app/app.py", line 185, in func
    gary_frame = cv2.cvtColor(roi, cv2.COLOR_RGB2GRAY)
cv2.error: OpenCV(4.2.0) /io/opencv/modules/imgproc/src/color.cpp:182: error: (-215:Assertion failed) !_src.empty() in function 'cvtColor'

Exception on / [POST]
Traceback (most recent call last):
  File "/home/ubuntu/.local/lib/python3.6/site-packages/flask/app.py", line 2447, in wsgi_app
    response = self.full_dispatch_request()
  File "/home/ubuntu/.local/lib/python3.6/site-packages/flask/app.py", line 1952, in full_dispatch_request
    rv = self.handle_user_exception(e)
  File "/home/ubuntu/.local/lib/python3.6/site-packages/flask/app.py", line 1821, in handle_user_exception
    reraise(exc_type, exc_value, tb)
  File "/home/ubuntu/.local/lib/python3.6/site-packages/flask/_compat.py", line 39, in reraise
    raise value
  File "/home/ubuntu/.local/lib/python3.6/site-packages/flask/app.py", line 1950, in full_dispatch_request
    rv = self.dispatch_request()
  File "/home/ubuntu/.local/lib/python3.6/site-packages/flask/app.py", line 1936, in dispatch_request
    return self.view_functions[rule.endpoint](**req.view_args)
  File "/home/ubuntu/flask_gunicorn_nginx_docker/flask_app/app.py", line 185, in func
    gary_frame = cv2.cvtColor(roi, cv2.COLOR_RGB2GRAY)
cv2.error: OpenCV(4.2.0) /io/opencv/modules/imgproc/src/color.cpp:182: error: (-215:Assertion failed) !_src.empty() in function 'cvtColor'

Exception on / [POST]
Traceback (most recent call last):
  File "/home/ubuntu/.local/lib/python3.6/site-packages/flask/app.py", line 2447, in wsgi_app
    response = self.full_dispatch_request()
  File "/home/ubuntu/.local/lib/python3.6/site-packages/flask/app.py", line 1952, in full_dispatch_request
    rv = self.handle_user_exception(e)
  File "/home/ubuntu/.local/lib/python3.6/site-packages/flask/app.py", line 1821, in handle_user_exception
    reraise(exc_type, exc_value, tb)
  File "/home/ubuntu/.local/lib/python3.6/site-packages/flask/_compat.py", line 39, in reraise
    raise value
  File "/home/ubuntu/.local/lib/python3.6/site-packages/flask/app.py", line 1950, in full_dispatch_request
    rv = self.dispatch_request()
  File "/home/ubuntu/.local/lib/python3.6/site-packages/flask/app.py", line 1936, in dispatch_request
    return self.view_functions[rule.endpoint](**req.view_args)
  File "/home/ubuntu/flask_gunicorn_nginx_docker/flask_app/app.py", line 185, in func
    gary_frame = cv2.cvtColor(roi, cv2.COLOR_RGB2GRAY)
cv2.error: OpenCV(4.2.0) /io/opencv/modules/imgproc/src/color.cpp:182: error: (-215:Assertion failed) !_src.empty() in function 'cvtColor'

Exception on / [POST]
Traceback (most recent call last):
  File "/home/ubuntu/.local/lib/python3.6/site-packages/flask/app.py", line 2447, in wsgi_app
    response = self.full_dispatch_request()
  File "/home/ubuntu/.local/lib/python3.6/site-packages/flask/app.py", line 1952, in full_dispatch_request
    rv = self.handle_user_exception(e)
  File "/home/ubuntu/.local/lib/python3.6/site-packages/flask/app.py", line 1821, in handle_user_exception
    reraise(exc_type, exc_value, tb)
  File "/home/ubuntu/.local/lib/python3.6/site-packages/flask/_compat.py", line 39, in reraise
    raise value
  File "/home/ubuntu/.local/lib/python3.6/site-packages/flask/app.py", line 1950, in full_dispatch_request
    rv = self.dispatch_request()
  File "/home/ubuntu/.local/lib/python3.6/site-packages/flask/app.py", line 1936, in dispatch_request
    return self.view_functions[rule.endpoint](**req.view_args)
  File "/home/ubuntu/flask_gunicorn_nginx_docker/flask_app/app.py", line 185, in func
    gary_frame = cv2.cvtColor(roi, cv2.COLOR_RGB2GRAY)
cv2.error: OpenCV(4.2.0) /io/opencv/modules/imgproc/src/color.cpp:182: error: (-215:Assertion failed) !_src.empty() in function 'cvtColor'

Exception on / [POST]
Traceback (most recent call last):
  File "/home/ubuntu/.local/lib/python3.6/site-packages/flask/app.py", line 2447, in wsgi_app
    response = self.full_dispatch_request()
  File "/home/ubuntu/.local/lib/python3.6/site-packages/flask/app.py", line 1952, in full_dispatch_request
    rv = self.handle_user_exception(e)
  File "/home/ubuntu/.local/lib/python3.6/site-packages/flask/app.py", line 1821, in handle_user_exception
    reraise(exc_type, exc_value, tb)
  File "/home/ubuntu/.local/lib/python3.6/site-packages/flask/_compat.py", line 39, in reraise
    raise value
  File "/home/ubuntu/.local/lib/python3.6/site-packages/flask/app.py", line 1950, in full_dispatch_request
    rv = self.dispatch_request()
  File "/home/ubuntu/.local/lib/python3.6/site-packages/flask/app.py", line 1936, in dispatch_request
    return self.view_functions[rule.endpoint](**req.view_args)
  File "/home/ubuntu/flask_gunicorn_nginx_docker/flask_app/app.py", line 185, in func
    gary_frame = cv2.cvtColor(roi, cv2.COLOR_RGB2GRAY)
cv2.error: OpenCV(4.2.0) /io/opencv/modules/imgproc/src/color.cpp:182: error: (-215:Assertion failed) !_src.empty() in function 'cvtColor'

Exception on / [POST]
Traceback (most recent call last):
  File "/home/ubuntu/.local/lib/python3.6/site-packages/flask/app.py", line 2447, in wsgi_app
    response = self.full_dispatch_request()
  File "/home/ubuntu/.local/lib/python3.6/site-packages/flask/app.py", line 1952, in full_dispatch_request
    rv = self.handle_user_exception(e)
  File "/home/ubuntu/.local/lib/python3.6/site-packages/flask/app.py", line 1821, in handle_user_exception
    reraise(exc_type, exc_value, tb)
  File "/home/ubuntu/.local/lib/python3.6/site-packages/flask/_compat.py", line 39, in reraise
    raise value
  File "/home/ubuntu/.local/lib/python3.6/site-packages/flask/app.py", line 1950, in full_dispatch_request
    rv = self.dispatch_request()
  File "/home/ubuntu/.local/lib/python3.6/site-packages/flask/app.py", line 1936, in dispatch_request
    return self.view_functions[rule.endpoint](**req.view_args)
  File "/home/ubuntu/flask_gunicorn_nginx_docker/flask_app/app.py", line 185, in func
    gary_frame = cv2.cvtColor(roi, cv2.COLOR_RGB2GRAY)
cv2.error: OpenCV(4.2.0) /io/opencv/modules/imgproc/src/color.cpp:182: error: (-215:Assertion failed) !_src.empty() in function 'cvtColor'

Exception on / [POST]
Traceback (most recent call last):
  File "/home/ubuntu/.local/lib/python3.6/site-packages/flask/app.py", line 2447, in wsgi_app
    response = self.full_dispatch_request()
  File "/home/ubuntu/.local/lib/python3.6/site-packages/flask/app.py", line 1952, in full_dispatch_request
    rv = self.handle_user_exception(e)
  File "/home/ubuntu/.local/lib/python3.6/site-packages/flask/app.py", line 1821, in handle_user_exception
    reraise(exc_type, exc_value, tb)
  File "/home/ubuntu/.local/lib/python3.6/site-packages/flask/_compat.py", line 39, in reraise
    raise value
  File "/home/ubuntu/.local/lib/python3.6/site-packages/flask/app.py", line 1950, in full_dispatch_request
    rv = self.dispatch_request()
  File "/home/ubuntu/.local/lib/python3.6/site-packages/flask/app.py", line 1936, in dispatch_request
    return self.view_functions[rule.endpoint](**req.view_args)
  File "/home/ubuntu/flask_gunicorn_nginx_docker/flask_app/app.py", line 185, in func
    gary_frame = cv2.cvtColor(roi, cv2.COLOR_RGB2GRAY)
cv2.error: OpenCV(4.2.0) /io/opencv/modules/imgproc/src/color.cpp:182: error: (-215:Assertion failed) !_src.empty() in function 'cvtColor'

Exception on / [POST]
Traceback (most recent call last):
  File "/home/ubuntu/.local/lib/python3.6/site-packages/flask/app.py", line 2447, in wsgi_app
    response = self.full_dispatch_request()
  File "/home/ubuntu/.local/lib/python3.6/site-packages/flask/app.py", line 1952, in full_dispatch_request
    rv = self.handle_user_exception(e)
  File "/home/ubuntu/.local/lib/python3.6/site-packages/flask/app.py", line 1821, in handle_user_exception
    reraise(exc_type, exc_value, tb)
  File "/home/ubuntu/.local/lib/python3.6/site-packages/flask/_compat.py", line 39, in reraise
    raise value
  File "/home/ubuntu/.local/lib/python3.6/site-packages/flask/app.py", line 1950, in full_dispatch_request
    rv = self.dispatch_request()
  File "/home/ubuntu/.local/lib/python3.6/site-packages/flask/app.py", line 1936, in dispatch_request
    return self.view_functions[rule.endpoint](**req.view_args)
  File "/home/ubuntu/flask_gunicorn_nginx_docker/flask_app/app.py", line 185, in func
    gary_frame = cv2.cvtColor(roi, cv2.COLOR_RGB2GRAY)
cv2.error: OpenCV(4.2.0) /io/opencv/modules/imgproc/src/color.cpp:182: error: (-215:Assertion failed) !_src.empty() in function 'cvtColor'

Exception on / [POST]
Traceback (most recent call last):
  File "/home/ubuntu/.local/lib/python3.6/site-packages/flask/app.py", line 2447, in wsgi_app
    response = self.full_dispatch_request()
  File "/home/ubuntu/.local/lib/python3.6/site-packages/flask/app.py", line 1952, in full_dispatch_request
    rv = self.handle_user_exception(e)
  File "/home/ubuntu/.local/lib/python3.6/site-packages/flask/app.py", line 1821, in handle_user_exception
    reraise(exc_type, exc_value, tb)
  File "/home/ubuntu/.local/lib/python3.6/site-packages/flask/_compat.py", line 39, in reraise
    raise value
  File "/home/ubuntu/.local/lib/python3.6/site-packages/flask/app.py", line 1950, in full_dispatch_request
    rv = self.dispatch_request()
  File "/home/ubuntu/.local/lib/python3.6/site-packages/flask/app.py", line 1936, in dispatch_request
    return self.view_functions[rule.endpoint](**req.view_args)
  File "/home/ubuntu/flask_gunicorn_nginx_docker/flask_app/app.py", line 185, in func
    gary_frame = cv2.cvtColor(roi, cv2.COLOR_RGB2GRAY)
cv2.error: OpenCV(4.2.0) /io/opencv/modules/imgproc/src/color.cpp:182: error: (-215:Assertion failed) !_src.empty() in function 'cvtColor'

Exception on / [POST]
Traceback (most recent call last):
  File "/home/ubuntu/.local/lib/python3.6/site-packages/flask/app.py", line 2447, in wsgi_app
    response = self.full_dispatch_request()
  File "/home/ubuntu/.local/lib/python3.6/site-packages/flask/app.py", line 1952, in full_dispatch_request
    rv = self.handle_user_exception(e)
  File "/home/ubuntu/.local/lib/python3.6/site-packages/flask/app.py", line 1821, in handle_user_exception
    reraise(exc_type, exc_value, tb)
  File "/home/ubuntu/.local/lib/python3.6/site-packages/flask/_compat.py", line 39, in reraise
    raise value
  File "/home/ubuntu/.local/lib/python3.6/site-packages/flask/app.py", line 1950, in full_dispatch_request
    rv = self.dispatch_request()
  File "/home/ubuntu/.local/lib/python3.6/site-packages/flask/app.py", line 1936, in dispatch_request
    return self.view_functions[rule.endpoint](**req.view_args)
  File "/home/ubuntu/flask_gunicorn_nginx_docker/flask_app/app.py", line 185, in func
    gary_frame = cv2.cvtColor(roi, cv2.COLOR_RGB2GRAY)
cv2.error: OpenCV(4.2.0) /io/opencv/modules/imgproc/src/color.cpp:182: error: (-215:Assertion failed) !_src.empty() in function 'cvtColor'

Exception on / [POST]
Traceback (most recent call last):
  File "/home/ubuntu/.local/lib/python3.6/site-packages/flask/app.py", line 2447, in wsgi_app
    response = self.full_dispatch_request()
  File "/home/ubuntu/.local/lib/python3.6/site-packages/flask/app.py", line 1952, in full_dispatch_request
    rv = self.handle_user_exception(e)
  File "/home/ubuntu/.local/lib/python3.6/site-packages/flask/app.py", line 1821, in handle_user_exception
    reraise(exc_type, exc_value, tb)
  File "/home/ubuntu/.local/lib/python3.6/site-packages/flask/_compat.py", line 39, in reraise
    raise value
  File "/home/ubuntu/.local/lib/python3.6/site-packages/flask/app.py", line 1950, in full_dispatch_request
    rv = self.dispatch_request()
  File "/home/ubuntu/.local/lib/python3.6/site-packages/flask/app.py", line 1936, in dispatch_request
    return self.view_functions[rule.endpoint](**req.view_args)
  File "/home/ubuntu/flask_gunicorn_nginx_docker/flask_app/app.py", line 185, in func
    gary_frame = cv2.cvtColor(roi, cv2.COLOR_RGB2GRAY)
cv2.error: OpenCV(4.2.0) /io/opencv/modules/imgproc/src/color.cpp:182: error: (-215:Assertion failed) !_src.empty() in function 'cvtColor'

Exception on / [POST]
Traceback (most recent call last):
  File "/home/ubuntu/.local/lib/python3.6/site-packages/flask/app.py", line 2447, in wsgi_app
    response = self.full_dispatch_request()
  File "/home/ubuntu/.local/lib/python3.6/site-packages/flask/app.py", line 1952, in full_dispatch_request
    rv = self.handle_user_exception(e)
  File "/home/ubuntu/.local/lib/python3.6/site-packages/flask/app.py", line 1821, in handle_user_exception
    reraise(exc_type, exc_value, tb)
  File "/home/ubuntu/.local/lib/python3.6/site-packages/flask/_compat.py", line 39, in reraise
    raise value
  File "/home/ubuntu/.local/lib/python3.6/site-packages/flask/app.py", line 1950, in full_dispatch_request
    rv = self.dispatch_request()
  File "/home/ubuntu/.local/lib/python3.6/site-packages/flask/app.py", line 1936, in dispatch_request
    return self.view_functions[rule.endpoint](**req.view_args)
  File "/home/ubuntu/flask_gunicorn_nginx_docker/flask_app/app.py", line 185, in func
    gary_frame = cv2.cvtColor(roi, cv2.COLOR_RGB2GRAY)
cv2.error: OpenCV(4.2.0) /io/opencv/modules/imgproc/src/color.cpp:182: error: (-215:Assertion failed) !_src.empty() in function 'cvtColor'

Exception on / [POST]
Traceback (most recent call last):
  File "/home/ubuntu/.local/lib/python3.6/site-packages/flask/app.py", line 2447, in wsgi_app
    response = self.full_dispatch_request()
  File "/home/ubuntu/.local/lib/python3.6/site-packages/flask/app.py", line 1952, in full_dispatch_request
    rv = self.handle_user_exception(e)
  File "/home/ubuntu/.local/lib/python3.6/site-packages/flask/app.py", line 1821, in handle_user_exception
    reraise(exc_type, exc_value, tb)
  File "/home/ubuntu/.local/lib/python3.6/site-packages/flask/_compat.py", line 39, in reraise
    raise value
  File "/home/ubuntu/.local/lib/python3.6/site-packages/flask/app.py", line 1950, in full_dispatch_request
    rv = self.dispatch_request()
  File "/home/ubuntu/.local/lib/python3.6/site-packages/flask/app.py", line 1936, in dispatch_request
    return self.view_functions[rule.endpoint](**req.view_args)
  File "/home/ubuntu/flask_gunicorn_nginx_docker/flask_app/app.py", line 185, in func
    gary_frame = cv2.cvtColor(roi, cv2.COLOR_RGB2GRAY)
cv2.error: OpenCV(4.2.0) /io/opencv/modules/imgproc/src/color.cpp:182: error: (-215:Assertion failed) !_src.empty() in function 'cvtColor'

Exception on / [POST]
Traceback (most recent call last):
  File "/home/ubuntu/.local/lib/python3.6/site-packages/flask/app.py", line 2447, in wsgi_app
    response = self.full_dispatch_request()
  File "/home/ubuntu/.local/lib/python3.6/site-packages/flask/app.py", line 1952, in full_dispatch_request
    rv = self.handle_user_exception(e)
  File "/home/ubuntu/.local/lib/python3.6/site-packages/flask/app.py", line 1821, in handle_user_exception
    reraise(exc_type, exc_value, tb)
  File "/home/ubuntu/.local/lib/python3.6/site-packages/flask/_compat.py", line 39, in reraise
    raise value
  File "/home/ubuntu/.local/lib/python3.6/site-packages/flask/app.py", line 1950, in full_dispatch_request
    rv = self.dispatch_request()
  File "/home/ubuntu/.local/lib/python3.6/site-packages/flask/app.py", line 1936, in dispatch_request
    return self.view_functions[rule.endpoint](**req.view_args)
  File "/home/ubuntu/flask_gunicorn_nginx_docker/flask_app/app.py", line 185, in func
    gary_frame = cv2.cvtColor(roi, cv2.COLOR_RGB2GRAY)
cv2.error: OpenCV(4.2.0) /io/opencv/modules/imgproc/src/color.cpp:182: error: (-215:Assertion failed) !_src.empty() in function 'cvtColor'

Exception on / [POST]
Traceback (most recent call last):
  File "/home/ubuntu/.local/lib/python3.6/site-packages/flask/app.py", line 2447, in wsgi_app
    response = self.full_dispatch_request()
  File "/home/ubuntu/.local/lib/python3.6/site-packages/flask/app.py", line 1952, in full_dispatch_request
    rv = self.handle_user_exception(e)
  File "/home/ubuntu/.local/lib/python3.6/site-packages/flask/app.py", line 1821, in handle_user_exception
    reraise(exc_type, exc_value, tb)
  File "/home/ubuntu/.local/lib/python3.6/site-packages/flask/_compat.py", line 39, in reraise
    raise value
  File "/home/ubuntu/.local/lib/python3.6/site-packages/flask/app.py", line 1950, in full_dispatch_request
    rv = self.dispatch_request()
  File "/home/ubuntu/.local/lib/python3.6/site-packages/flask/app.py", line 1936, in dispatch_request
    return self.view_functions[rule.endpoint](**req.view_args)
  File "/home/ubuntu/flask_gunicorn_nginx_docker/flask_app/app.py", line 185, in func
    gary_frame = cv2.cvtColor(roi, cv2.COLOR_RGB2GRAY)
cv2.error: OpenCV(4.2.0) /io/opencv/modules/imgproc/src/color.cpp:182: error: (-215:Assertion failed) !_src.empty() in function 'cvtColor'

Exception on / [POST]
Traceback (most recent call last):
  File "/home/ubuntu/.local/lib/python3.6/site-packages/flask/app.py", line 2447, in wsgi_app
    response = self.full_dispatch_request()
  File "/home/ubuntu/.local/lib/python3.6/site-packages/flask/app.py", line 1952, in full_dispatch_request
    rv = self.handle_user_exception(e)
  File "/home/ubuntu/.local/lib/python3.6/site-packages/flask/app.py", line 1821, in handle_user_exception
    reraise(exc_type, exc_value, tb)
  File "/home/ubuntu/.local/lib/python3.6/site-packages/flask/_compat.py", line 39, in reraise
    raise value
  File "/home/ubuntu/.local/lib/python3.6/site-packages/flask/app.py", line 1950, in full_dispatch_request
    rv = self.dispatch_request()
  File "/home/ubuntu/.local/lib/python3.6/site-packages/flask/app.py", line 1936, in dispatch_request
    return self.view_functions[rule.endpoint](**req.view_args)
  File "/home/ubuntu/flask_gunicorn_nginx_docker/flask_app/app.py", line 185, in func
    gary_frame = cv2.cvtColor(roi, cv2.COLOR_RGB2GRAY)
cv2.error: OpenCV(4.2.0) /io/opencv/modules/imgproc/src/color.cpp:182: error: (-215:Assertion failed) !_src.empty() in function 'cvtColor'

Exception on / [POST]
Traceback (most recent call last):
  File "/home/ubuntu/.local/lib/python3.6/site-packages/flask/app.py", line 2447, in wsgi_app
    response = self.full_dispatch_request()
  File "/home/ubuntu/.local/lib/python3.6/site-packages/flask/app.py", line 1952, in full_dispatch_request
    rv = self.handle_user_exception(e)
  File "/home/ubuntu/.local/lib/python3.6/site-packages/flask/app.py", line 1821, in handle_user_exception
    reraise(exc_type, exc_value, tb)
  File "/home/ubuntu/.local/lib/python3.6/site-packages/flask/_compat.py", line 39, in reraise
    raise value
  File "/home/ubuntu/.local/lib/python3.6/site-packages/flask/app.py", line 1950, in full_dispatch_request
    rv = self.dispatch_request()
  File "/home/ubuntu/.local/lib/python3.6/site-packages/flask/app.py", line 1936, in dispatch_request
    return self.view_functions[rule.endpoint](**req.view_args)
  File "/home/ubuntu/flask_gunicorn_nginx_docker/flask_app/app.py", line 185, in func
    gary_frame = cv2.cvtColor(roi, cv2.COLOR_RGB2GRAY)
cv2.error: OpenCV(4.2.0) /io/opencv/modules/imgproc/src/color.cpp:182: error: (-215:Assertion failed) !_src.empty() in function 'cvtColor'

Exception on / [POST]
Traceback (most recent call last):
  File "/home/ubuntu/.local/lib/python3.6/site-packages/flask/app.py", line 2447, in wsgi_app
    response = self.full_dispatch_request()
  File "/home/ubuntu/.local/lib/python3.6/site-packages/flask/app.py", line 1952, in full_dispatch_request
    rv = self.handle_user_exception(e)
  File "/home/ubuntu/.local/lib/python3.6/site-packages/flask/app.py", line 1821, in handle_user_exception
    reraise(exc_type, exc_value, tb)
  File "/home/ubuntu/.local/lib/python3.6/site-packages/flask/_compat.py", line 39, in reraise
    raise value
  File "/home/ubuntu/.local/lib/python3.6/site-packages/flask/app.py", line 1950, in full_dispatch_request
    rv = self.dispatch_request()
  File "/home/ubuntu/.local/lib/python3.6/site-packages/flask/app.py", line 1936, in dispatch_request
    return self.view_functions[rule.endpoint](**req.view_args)
  File "/home/ubuntu/flask_gunicorn_nginx_docker/flask_app/app.py", line 185, in func
    gary_frame = cv2.cvtColor(roi, cv2.COLOR_RGB2GRAY)
cv2.error: OpenCV(4.2.0) /io/opencv/modules/imgproc/src/color.cpp:182: error: (-215:Assertion failed) !_src.empty() in function 'cvtColor'

Exception on / [POST]
Traceback (most recent call last):
  File "/home/ubuntu/.local/lib/python3.6/site-packages/flask/app.py", line 2447, in wsgi_app
    response = self.full_dispatch_request()
  File "/home/ubuntu/.local/lib/python3.6/site-packages/flask/app.py", line 1952, in full_dispatch_request
    rv = self.handle_user_exception(e)
  File "/home/ubuntu/.local/lib/python3.6/site-packages/flask/app.py", line 1821, in handle_user_exception
    reraise(exc_type, exc_value, tb)
  File "/home/ubuntu/.local/lib/python3.6/site-packages/flask/_compat.py", line 39, in reraise
    raise value
  File "/home/ubuntu/.local/lib/python3.6/site-packages/flask/app.py", line 1950, in full_dispatch_request
    rv = self.dispatch_request()
  File "/home/ubuntu/.local/lib/python3.6/site-packages/flask/app.py", line 1936, in dispatch_request
    return self.view_functions[rule.endpoint](**req.view_args)
  File "/home/ubuntu/flask_gunicorn_nginx_docker/flask_app/app.py", line 185, in func
    gary_frame = cv2.cvtColor(roi, cv2.COLOR_RGB2GRAY)
cv2.error: OpenCV(4.2.0) /io/opencv/modules/imgproc/src/color.cpp:182: error: (-215:Assertion failed) !_src.empty() in function 'cvtColor'

Exception on / [POST]
Traceback (most recent call last):
  File "/home/ubuntu/.local/lib/python3.6/site-packages/flask/app.py", line 2447, in wsgi_app
    response = self.full_dispatch_request()
  File "/home/ubuntu/.local/lib/python3.6/site-packages/flask/app.py", line 1952, in full_dispatch_request
    rv = self.handle_user_exception(e)
  File "/home/ubuntu/.local/lib/python3.6/site-packages/flask/app.py", line 1821, in handle_user_exception
    reraise(exc_type, exc_value, tb)
  File "/home/ubuntu/.local/lib/python3.6/site-packages/flask/_compat.py", line 39, in reraise
    raise value
  File "/home/ubuntu/.local/lib/python3.6/site-packages/flask/app.py", line 1950, in full_dispatch_request
    rv = self.dispatch_request()
  File "/home/ubuntu/.local/lib/python3.6/site-packages/flask/app.py", line 1936, in dispatch_request
    return self.view_functions[rule.endpoint](**req.view_args)
  File "/home/ubuntu/flask_gunicorn_nginx_docker/flask_app/app.py", line 185, in func
    gary_frame = cv2.cvtColor(roi, cv2.COLOR_RGB2GRAY)
cv2.error: OpenCV(4.2.0) /io/opencv/modules/imgproc/src/color.cpp:182: error: (-215:Assertion failed) !_src.empty() in function 'cvtColor'

Exception on / [POST]
Traceback (most recent call last):
  File "/home/ubuntu/.local/lib/python3.6/site-packages/flask/app.py", line 2447, in wsgi_app
    response = self.full_dispatch_request()
  File "/home/ubuntu/.local/lib/python3.6/site-packages/flask/app.py", line 1952, in full_dispatch_request
    rv = self.handle_user_exception(e)
  File "/home/ubuntu/.local/lib/python3.6/site-packages/flask/app.py", line 1821, in handle_user_exception
    reraise(exc_type, exc_value, tb)
  File "/home/ubuntu/.local/lib/python3.6/site-packages/flask/_compat.py", line 39, in reraise
    raise value
  File "/home/ubuntu/.local/lib/python3.6/site-packages/flask/app.py", line 1950, in full_dispatch_request
    rv = self.dispatch_request()
  File "/home/ubuntu/.local/lib/python3.6/site-packages/flask/app.py", line 1936, in dispatch_request
    return self.view_functions[rule.endpoint](**req.view_args)
  File "/home/ubuntu/flask_gunicorn_nginx_docker/flask_app/app.py", line 185, in func
    gary_frame = cv2.cvtColor(roi, cv2.COLOR_RGB2GRAY)
cv2.error: OpenCV(4.2.0) /io/opencv/modules/imgproc/src/color.cpp:182: error: (-215:Assertion failed) !_src.empty() in function 'cvtColor'

Exception on / [POST]
Traceback (most recent call last):
  File "/home/ubuntu/.local/lib/python3.6/site-packages/flask/app.py", line 2447, in wsgi_app
    response = self.full_dispatch_request()
  File "/home/ubuntu/.local/lib/python3.6/site-packages/flask/app.py", line 1952, in full_dispatch_request
    rv = self.handle_user_exception(e)
  File "/home/ubuntu/.local/lib/python3.6/site-packages/flask/app.py", line 1821, in handle_user_exception
    reraise(exc_type, exc_value, tb)
  File "/home/ubuntu/.local/lib/python3.6/site-packages/flask/_compat.py", line 39, in reraise
    raise value
  File "/home/ubuntu/.local/lib/python3.6/site-packages/flask/app.py", line 1950, in full_dispatch_request
    rv = self.dispatch_request()
  File "/home/ubuntu/.local/lib/python3.6/site-packages/flask/app.py", line 1936, in dispatch_request
    return self.view_functions[rule.endpoint](**req.view_args)
  File "/home/ubuntu/flask_gunicorn_nginx_docker/flask_app/app.py", line 185, in func
    gary_frame = cv2.cvtColor(roi, cv2.COLOR_RGB2GRAY)
cv2.error: OpenCV(4.2.0) /io/opencv/modules/imgproc/src/color.cpp:182: error: (-215:Assertion failed) !_src.empty() in function 'cvtColor'

Exception on / [POST]
Traceback (most recent call last):
  File "/home/ubuntu/.local/lib/python3.6/site-packages/flask/app.py", line 2447, in wsgi_app
    response = self.full_dispatch_request()
  File "/home/ubuntu/.local/lib/python3.6/site-packages/flask/app.py", line 1952, in full_dispatch_request
    rv = self.handle_user_exception(e)
  File "/home/ubuntu/.local/lib/python3.6/site-packages/flask/app.py", line 1821, in handle_user_exception
    reraise(exc_type, exc_value, tb)
  File "/home/ubuntu/.local/lib/python3.6/site-packages/flask/_compat.py", line 39, in reraise
    raise value
  File "/home/ubuntu/.local/lib/python3.6/site-packages/flask/app.py", line 1950, in full_dispatch_request
    rv = self.dispatch_request()
  File "/home/ubuntu/.local/lib/python3.6/site-packages/flask/app.py", line 1936, in dispatch_request
    return self.view_functions[rule.endpoint](**req.view_args)
  File "/home/ubuntu/flask_gunicorn_nginx_docker/flask_app/app.py", line 185, in func
    gary_frame = cv2.cvtColor(roi, cv2.COLOR_RGB2GRAY)
cv2.error: OpenCV(4.2.0) /io/opencv/modules/imgproc/src/color.cpp:182: error: (-215:Assertion failed) !_src.empty() in function 'cvtColor'

Exception on / [POST]
Traceback (most recent call last):
  File "/home/ubuntu/.local/lib/python3.6/site-packages/flask/app.py", line 2447, in wsgi_app
    response = self.full_dispatch_request()
  File "/home/ubuntu/.local/lib/python3.6/site-packages/flask/app.py", line 1952, in full_dispatch_request
    rv = self.handle_user_exception(e)
  File "/home/ubuntu/.local/lib/python3.6/site-packages/flask/app.py", line 1821, in handle_user_exception
    reraise(exc_type, exc_value, tb)
  File "/home/ubuntu/.local/lib/python3.6/site-packages/flask/_compat.py", line 39, in reraise
    raise value
  File "/home/ubuntu/.local/lib/python3.6/site-packages/flask/app.py", line 1950, in full_dispatch_request
    rv = self.dispatch_request()
  File "/home/ubuntu/.local/lib/python3.6/site-packages/flask/app.py", line 1936, in dispatch_request
    return self.view_functions[rule.endpoint](**req.view_args)
  File "/home/ubuntu/flask_gunicorn_nginx_docker/flask_app/app.py", line 185, in func
    gary_frame = cv2.cvtColor(roi, cv2.COLOR_RGB2GRAY)
cv2.error: OpenCV(4.2.0) /io/opencv/modules/imgproc/src/color.cpp:182: error: (-215:Assertion failed) !_src.empty() in function 'cvtColor'

Exception on / [POST]
Traceback (most recent call last):
  File "/home/ubuntu/.local/lib/python3.6/site-packages/flask/app.py", line 2447, in wsgi_app
    response = self.full_dispatch_request()
  File "/home/ubuntu/.local/lib/python3.6/site-packages/flask/app.py", line 1952, in full_dispatch_request
    rv = self.handle_user_exception(e)
  File "/home/ubuntu/.local/lib/python3.6/site-packages/flask/app.py", line 1821, in handle_user_exception
    reraise(exc_type, exc_value, tb)
  File "/home/ubuntu/.local/lib/python3.6/site-packages/flask/_compat.py", line 39, in reraise
    raise value
  File "/home/ubuntu/.local/lib/python3.6/site-packages/flask/app.py", line 1950, in full_dispatch_request
    rv = self.dispatch_request()
  File "/home/ubuntu/.local/lib/python3.6/site-packages/flask/app.py", line 1936, in dispatch_request
    return self.view_functions[rule.endpoint](**req.view_args)
  File "/home/ubuntu/flask_gunicorn_nginx_docker/flask_app/app.py", line 185, in func
    gary_frame = cv2.cvtColor(roi, cv2.COLOR_RGB2GRAY)
cv2.error: OpenCV(4.2.0) /io/opencv/modules/imgproc/src/color.cpp:182: error: (-215:Assertion failed) !_src.empty() in function 'cvtColor'

Exception on / [POST]
Traceback (most recent call last):
  File "/home/ubuntu/.local/lib/python3.6/site-packages/flask/app.py", line 2447, in wsgi_app
    response = self.full_dispatch_request()
  File "/home/ubuntu/.local/lib/python3.6/site-packages/flask/app.py", line 1952, in full_dispatch_request
    rv = self.handle_user_exception(e)
  File "/home/ubuntu/.local/lib/python3.6/site-packages/flask/app.py", line 1821, in handle_user_exception
    reraise(exc_type, exc_value, tb)
  File "/home/ubuntu/.local/lib/python3.6/site-packages/flask/_compat.py", line 39, in reraise
    raise value
  File "/home/ubuntu/.local/lib/python3.6/site-packages/flask/app.py", line 1950, in full_dispatch_request
    rv = self.dispatch_request()
  File "/home/ubuntu/.local/lib/python3.6/site-packages/flask/app.py", line 1936, in dispatch_request
    return self.view_functions[rule.endpoint](**req.view_args)
  File "/home/ubuntu/flask_gunicorn_nginx_docker/flask_app/app.py", line 185, in func
    gary_frame = cv2.cvtColor(roi, cv2.COLOR_RGB2GRAY)
cv2.error: OpenCV(4.2.0) /io/opencv/modules/imgproc/src/color.cpp:182: error: (-215:Assertion failed) !_src.empty() in function 'cvtColor'

Exception on / [POST]
Traceback (most recent call last):
  File "/home/ubuntu/.local/lib/python3.6/site-packages/flask/app.py", line 2447, in wsgi_app
    response = self.full_dispatch_request()
  File "/home/ubuntu/.local/lib/python3.6/site-packages/flask/app.py", line 1952, in full_dispatch_request
    rv = self.handle_user_exception(e)
  File "/home/ubuntu/.local/lib/python3.6/site-packages/flask/app.py", line 1821, in handle_user_exception
    reraise(exc_type, exc_value, tb)
  File "/home/ubuntu/.local/lib/python3.6/site-packages/flask/_compat.py", line 39, in reraise
    raise value
  File "/home/ubuntu/.local/lib/python3.6/site-packages/flask/app.py", line 1950, in full_dispatch_request
    rv = self.dispatch_request()
  File "/home/ubuntu/.local/lib/python3.6/site-packages/flask/app.py", line 1936, in dispatch_request
    return self.view_functions[rule.endpoint](**req.view_args)
  File "/home/ubuntu/flask_gunicorn_nginx_docker/flask_app/app.py", line 185, in func
    gary_frame = cv2.cvtColor(roi, cv2.COLOR_RGB2GRAY)
cv2.error: OpenCV(4.2.0) /io/opencv/modules/imgproc/src/color.cpp:182: error: (-215:Assertion failed) !_src.empty() in function 'cvtColor'

Exception on / [POST]
Traceback (most recent call last):
  File "/home/ubuntu/.local/lib/python3.6/site-packages/flask/app.py", line 2447, in wsgi_app
    response = self.full_dispatch_request()
  File "/home/ubuntu/.local/lib/python3.6/site-packages/flask/app.py", line 1952, in full_dispatch_request
    rv = self.handle_user_exception(e)
  File "/home/ubuntu/.local/lib/python3.6/site-packages/flask/app.py", line 1821, in handle_user_exception
    reraise(exc_type, exc_value, tb)
  File "/home/ubuntu/.local/lib/python3.6/site-packages/flask/_compat.py", line 39, in reraise
    raise value
  File "/home/ubuntu/.local/lib/python3.6/site-packages/flask/app.py", line 1950, in full_dispatch_request
    rv = self.dispatch_request()
  File "/home/ubuntu/.local/lib/python3.6/site-packages/flask/app.py", line 1936, in dispatch_request
    return self.view_functions[rule.endpoint](**req.view_args)
  File "/home/ubuntu/flask_gunicorn_nginx_docker/flask_app/app.py", line 185, in func
    gary_frame = cv2.cvtColor(roi, cv2.COLOR_RGB2GRAY)
cv2.error: OpenCV(4.2.0) /io/opencv/modules/imgproc/src/color.cpp:182: error: (-215:Assertion failed) !_src.empty() in function 'cvtColor'

Exception on / [POST]
Traceback (most recent call last):
  File "/home/ubuntu/.local/lib/python3.6/site-packages/flask/app.py", line 2447, in wsgi_app
    response = self.full_dispatch_request()
  File "/home/ubuntu/.local/lib/python3.6/site-packages/flask/app.py", line 1952, in full_dispatch_request
    rv = self.handle_user_exception(e)
  File "/home/ubuntu/.local/lib/python3.6/site-packages/flask/app.py", line 1821, in handle_user_exception
    reraise(exc_type, exc_value, tb)
  File "/home/ubuntu/.local/lib/python3.6/site-packages/flask/_compat.py", line 39, in reraise
    raise value
  File "/home/ubuntu/.local/lib/python3.6/site-packages/flask/app.py", line 1950, in full_dispatch_request
    rv = self.dispatch_request()
  File "/home/ubuntu/.local/lib/python3.6/site-packages/flask/app.py", line 1936, in dispatch_request
    return self.view_functions[rule.endpoint](**req.view_args)
  File "/home/ubuntu/flask_gunicorn_nginx_docker/flask_app/app.py", line 185, in func
    gary_frame = cv2.cvtColor(roi, cv2.COLOR_RGB2GRAY)
cv2.error: OpenCV(4.2.0) /io/opencv/modules/imgproc/src/color.cpp:182: error: (-215:Assertion failed) !_src.empty() in function 'cvtColor'

Exception on / [POST]
Traceback (most recent call last):
  File "/home/ubuntu/.local/lib/python3.6/site-packages/flask/app.py", line 2447, in wsgi_app
    response = self.full_dispatch_request()
  File "/home/ubuntu/.local/lib/python3.6/site-packages/flask/app.py", line 1952, in full_dispatch_request
    rv = self.handle_user_exception(e)
  File "/home/ubuntu/.local/lib/python3.6/site-packages/flask/app.py", line 1821, in handle_user_exception
    reraise(exc_type, exc_value, tb)
  File "/home/ubuntu/.local/lib/python3.6/site-packages/flask/_compat.py", line 39, in reraise
    raise value
  File "/home/ubuntu/.local/lib/python3.6/site-packages/flask/app.py", line 1950, in full_dispatch_request
    rv = self.dispatch_request()
  File "/home/ubuntu/.local/lib/python3.6/site-packages/flask/app.py", line 1936, in dispatch_request
    return self.view_functions[rule.endpoint](**req.view_args)
  File "/home/ubuntu/flask_gunicorn_nginx_docker/flask_app/app.py", line 185, in func
    gary_frame = cv2.cvtColor(roi, cv2.COLOR_RGB2GRAY)
cv2.error: OpenCV(4.2.0) /io/opencv/modules/imgproc/src/color.cpp:182: error: (-215:Assertion failed) !_src.empty() in function 'cvtColor'

Exception on / [POST]
Traceback (most recent call last):
  File "/home/ubuntu/.local/lib/python3.6/site-packages/flask/app.py", line 2447, in wsgi_app
    response = self.full_dispatch_request()
  File "/home/ubuntu/.local/lib/python3.6/site-packages/flask/app.py", line 1952, in full_dispatch_request
    rv = self.handle_user_exception(e)
  File "/home/ubuntu/.local/lib/python3.6/site-packages/flask/app.py", line 1821, in handle_user_exception
    reraise(exc_type, exc_value, tb)
  File "/home/ubuntu/.local/lib/python3.6/site-packages/flask/_compat.py", line 39, in reraise
    raise value
  File "/home/ubuntu/.local/lib/python3.6/site-packages/flask/app.py", line 1950, in full_dispatch_request
    rv = self.dispatch_request()
  File "/home/ubuntu/.local/lib/python3.6/site-packages/flask/app.py", line 1936, in dispatch_request
    return self.view_functions[rule.endpoint](**req.view_args)
  File "/home/ubuntu/flask_gunicorn_nginx_docker/flask_app/app.py", line 185, in func
    gary_frame = cv2.cvtColor(roi, cv2.COLOR_RGB2GRAY)
cv2.error: OpenCV(4.2.0) /io/opencv/modules/imgproc/src/color.cpp:182: error: (-215:Assertion failed) !_src.empty() in function 'cvtColor'

Exception on / [POST]
Traceback (most recent call last):
  File "/home/ubuntu/.local/lib/python3.6/site-packages/flask/app.py", line 2447, in wsgi_app
    response = self.full_dispatch_request()
  File "/home/ubuntu/.local/lib/python3.6/site-packages/flask/app.py", line 1952, in full_dispatch_request
    rv = self.handle_user_exception(e)
  File "/home/ubuntu/.local/lib/python3.6/site-packages/flask/app.py", line 1821, in handle_user_exception
    reraise(exc_type, exc_value, tb)
  File "/home/ubuntu/.local/lib/python3.6/site-packages/flask/_compat.py", line 39, in reraise
    raise value
  File "/home/ubuntu/.local/lib/python3.6/site-packages/flask/app.py", line 1950, in full_dispatch_request
    rv = self.dispatch_request()
  File "/home/ubuntu/.local/lib/python3.6/site-packages/flask/app.py", line 1936, in dispatch_request
    return self.view_functions[rule.endpoint](**req.view_args)
  File "/home/ubuntu/flask_gunicorn_nginx_docker/flask_app/app.py", line 185, in func
    gary_frame = cv2.cvtColor(roi, cv2.COLOR_RGB2GRAY)
cv2.error: OpenCV(4.2.0) /io/opencv/modules/imgproc/src/color.cpp:182: error: (-215:Assertion failed) !_src.empty() in function 'cvtColor'

Exception on / [POST]
Traceback (most recent call last):
  File "/home/ubuntu/.local/lib/python3.6/site-packages/flask/app.py", line 2447, in wsgi_app
    response = self.full_dispatch_request()
  File "/home/ubuntu/.local/lib/python3.6/site-packages/flask/app.py", line 1952, in full_dispatch_request
    rv = self.handle_user_exception(e)
  File "/home/ubuntu/.local/lib/python3.6/site-packages/flask/app.py", line 1821, in handle_user_exception
    reraise(exc_type, exc_value, tb)
  File "/home/ubuntu/.local/lib/python3.6/site-packages/flask/_compat.py", line 39, in reraise
    raise value
  File "/home/ubuntu/.local/lib/python3.6/site-packages/flask/app.py", line 1950, in full_dispatch_request
    rv = self.dispatch_request()
  File "/home/ubuntu/.local/lib/python3.6/site-packages/flask/app.py", line 1936, in dispatch_request
    return self.view_functions[rule.endpoint](**req.view_args)
  File "/home/ubuntu/flask_gunicorn_nginx_docker/flask_app/app.py", line 185, in func
    gary_frame = cv2.cvtColor(roi, cv2.COLOR_RGB2GRAY)
cv2.error: OpenCV(4.2.0) /io/opencv/modules/imgproc/src/color.cpp:182: error: (-215:Assertion failed) !_src.empty() in function 'cvtColor'

Exception on / [POST]
Traceback (most recent call last):
  File "/home/ubuntu/.local/lib/python3.6/site-packages/flask/app.py", line 2447, in wsgi_app
    response = self.full_dispatch_request()
  File "/home/ubuntu/.local/lib/python3.6/site-packages/flask/app.py", line 1952, in full_dispatch_request
    rv = self.handle_user_exception(e)
  File "/home/ubuntu/.local/lib/python3.6/site-packages/flask/app.py", line 1821, in handle_user_exception
    reraise(exc_type, exc_value, tb)
  File "/home/ubuntu/.local/lib/python3.6/site-packages/flask/_compat.py", line 39, in reraise
    raise value
  File "/home/ubuntu/.local/lib/python3.6/site-packages/flask/app.py", line 1950, in full_dispatch_request
    rv = self.dispatch_request()
  File "/home/ubuntu/.local/lib/python3.6/site-packages/flask/app.py", line 1936, in dispatch_request
    return self.view_functions[rule.endpoint](**req.view_args)
  File "/home/ubuntu/flask_gunicorn_nginx_docker/flask_app/app.py", line 185, in func
    gary_frame = cv2.cvtColor(roi, cv2.COLOR_RGB2GRAY)
cv2.error: OpenCV(4.2.0) /io/opencv/modules/imgproc/src/color.cpp:182: error: (-215:Assertion failed) !_src.empty() in function 'cvtColor'

Exception on / [POST]
Traceback (most recent call last):
  File "/home/ubuntu/.local/lib/python3.6/site-packages/flask/app.py", line 2447, in wsgi_app
    response = self.full_dispatch_request()
  File "/home/ubuntu/.local/lib/python3.6/site-packages/flask/app.py", line 1952, in full_dispatch_request
    rv = self.handle_user_exception(e)
  File "/home/ubuntu/.local/lib/python3.6/site-packages/flask/app.py", line 1821, in handle_user_exception
    reraise(exc_type, exc_value, tb)
  File "/home/ubuntu/.local/lib/python3.6/site-packages/flask/_compat.py", line 39, in reraise
    raise value
  File "/home/ubuntu/.local/lib/python3.6/site-packages/flask/app.py", line 1950, in full_dispatch_request
    rv = self.dispatch_request()
  File "/home/ubuntu/.local/lib/python3.6/site-packages/flask/app.py", line 1936, in dispatch_request
    return self.view_functions[rule.endpoint](**req.view_args)
  File "/home/ubuntu/flask_gunicorn_nginx_docker/flask_app/app.py", line 185, in func
    gary_frame = cv2.cvtColor(roi, cv2.COLOR_RGB2GRAY)
cv2.error: OpenCV(4.2.0) /io/opencv/modules/imgproc/src/color.cpp:182: error: (-215:Assertion failed) !_src.empty() in function 'cvtColor'

Exception on / [POST]
Traceback (most recent call last):
  File "/home/ubuntu/.local/lib/python3.6/site-packages/flask/app.py", line 2447, in wsgi_app
    response = self.full_dispatch_request()
  File "/home/ubuntu/.local/lib/python3.6/site-packages/flask/app.py", line 1952, in full_dispatch_request
    rv = self.handle_user_exception(e)
  File "/home/ubuntu/.local/lib/python3.6/site-packages/flask/app.py", line 1821, in handle_user_exception
    reraise(exc_type, exc_value, tb)
  File "/home/ubuntu/.local/lib/python3.6/site-packages/flask/_compat.py", line 39, in reraise
    raise value
  File "/home/ubuntu/.local/lib/python3.6/site-packages/flask/app.py", line 1950, in full_dispatch_request
    rv = self.dispatch_request()
  File "/home/ubuntu/.local/lib/python3.6/site-packages/flask/app.py", line 1936, in dispatch_request
    return self.view_functions[rule.endpoint](**req.view_args)
  File "/home/ubuntu/flask_gunicorn_nginx_docker/flask_app/app.py", line 185, in func
    gary_frame = cv2.cvtColor(roi, cv2.COLOR_RGB2GRAY)
cv2.error: OpenCV(4.2.0) /io/opencv/modules/imgproc/src/color.cpp:182: error: (-215:Assertion failed) !_src.empty() in function 'cvtColor'

Exception on / [POST]
Traceback (most recent call last):
  File "/home/ubuntu/.local/lib/python3.6/site-packages/flask/app.py", line 2447, in wsgi_app
    response = self.full_dispatch_request()
  File "/home/ubuntu/.local/lib/python3.6/site-packages/flask/app.py", line 1952, in full_dispatch_request
    rv = self.handle_user_exception(e)
  File "/home/ubuntu/.local/lib/python3.6/site-packages/flask/app.py", line 1821, in handle_user_exception
    reraise(exc_type, exc_value, tb)
  File "/home/ubuntu/.local/lib/python3.6/site-packages/flask/_compat.py", line 39, in reraise
    raise value
  File "/home/ubuntu/.local/lib/python3.6/site-packages/flask/app.py", line 1950, in full_dispatch_request
    rv = self.dispatch_request()
  File "/home/ubuntu/.local/lib/python3.6/site-packages/flask/app.py", line 1936, in dispatch_request
    return self.view_functions[rule.endpoint](**req.view_args)
  File "/home/ubuntu/flask_gunicorn_nginx_docker/flask_app/app.py", line 185, in func
    gary_frame = cv2.cvtColor(roi, cv2.COLOR_RGB2GRAY)
cv2.error: OpenCV(4.2.0) /io/opencv/modules/imgproc/src/color.cpp:182: error: (-215:Assertion failed) !_src.empty() in function 'cvtColor'

Exception on / [POST]
Traceback (most recent call last):
  File "/home/ubuntu/.local/lib/python3.6/site-packages/flask/app.py", line 2447, in wsgi_app
    response = self.full_dispatch_request()
  File "/home/ubuntu/.local/lib/python3.6/site-packages/flask/app.py", line 1952, in full_dispatch_request
    rv = self.handle_user_exception(e)
  File "/home/ubuntu/.local/lib/python3.6/site-packages/flask/app.py", line 1821, in handle_user_exception
    reraise(exc_type, exc_value, tb)
  File "/home/ubuntu/.local/lib/python3.6/site-packages/flask/_compat.py", line 39, in reraise
    raise value
  File "/home/ubuntu/.local/lib/python3.6/site-packages/flask/app.py", line 1950, in full_dispatch_request
    rv = self.dispatch_request()
  File "/home/ubuntu/.local/lib/python3.6/site-packages/flask/app.py", line 1936, in dispatch_request
    return self.view_functions[rule.endpoint](**req.view_args)
  File "/home/ubuntu/flask_gunicorn_nginx_docker/flask_app/app.py", line 185, in func
    gary_frame = cv2.cvtColor(roi, cv2.COLOR_RGB2GRAY)
cv2.error: OpenCV(4.2.0) /io/opencv/modules/imgproc/src/color.cpp:182: error: (-215:Assertion failed) !_src.empty() in function 'cvtColor'

Exception on / [POST]
Traceback (most recent call last):
  File "/home/ubuntu/.local/lib/python3.6/site-packages/flask/app.py", line 2447, in wsgi_app
    response = self.full_dispatch_request()
  File "/home/ubuntu/.local/lib/python3.6/site-packages/flask/app.py", line 1952, in full_dispatch_request
    rv = self.handle_user_exception(e)
  File "/home/ubuntu/.local/lib/python3.6/site-packages/flask/app.py", line 1821, in handle_user_exception
    reraise(exc_type, exc_value, tb)
  File "/home/ubuntu/.local/lib/python3.6/site-packages/flask/_compat.py", line 39, in reraise
    raise value
  File "/home/ubuntu/.local/lib/python3.6/site-packages/flask/app.py", line 1950, in full_dispatch_request
    rv = self.dispatch_request()
  File "/home/ubuntu/.local/lib/python3.6/site-packages/flask/app.py", line 1936, in dispatch_request
    return self.view_functions[rule.endpoint](**req.view_args)
  File "/home/ubuntu/flask_gunicorn_nginx_docker/flask_app/app.py", line 185, in func
    gary_frame = cv2.cvtColor(roi, cv2.COLOR_RGB2GRAY)
cv2.error: OpenCV(4.2.0) /io/opencv/modules/imgproc/src/color.cpp:182: error: (-215:Assertion failed) !_src.empty() in function 'cvtColor'

Exception on / [POST]
Traceback (most recent call last):
  File "/home/ubuntu/.local/lib/python3.6/site-packages/flask/app.py", line 2447, in wsgi_app
    response = self.full_dispatch_request()
  File "/home/ubuntu/.local/lib/python3.6/site-packages/flask/app.py", line 1952, in full_dispatch_request
    rv = self.handle_user_exception(e)
  File "/home/ubuntu/.local/lib/python3.6/site-packages/flask/app.py", line 1821, in handle_user_exception
    reraise(exc_type, exc_value, tb)
  File "/home/ubuntu/.local/lib/python3.6/site-packages/flask/_compat.py", line 39, in reraise
    raise value
  File "/home/ubuntu/.local/lib/python3.6/site-packages/flask/app.py", line 1950, in full_dispatch_request
    rv = self.dispatch_request()
  File "/home/ubuntu/.local/lib/python3.6/site-packages/flask/app.py", line 1936, in dispatch_request
    return self.view_functions[rule.endpoint](**req.view_args)
  File "/home/ubuntu/flask_gunicorn_nginx_docker/flask_app/app.py", line 185, in func
    gary_frame = cv2.cvtColor(roi, cv2.COLOR_RGB2GRAY)
cv2.error: OpenCV(4.2.0) /io/opencv/modules/imgproc/src/color.cpp:182: error: (-215:Assertion failed) !_src.empty() in function 'cvtColor'

Exception on / [POST]
Traceback (most recent call last):
  File "/home/ubuntu/.local/lib/python3.6/site-packages/flask/app.py", line 2447, in wsgi_app
    response = self.full_dispatch_request()
  File "/home/ubuntu/.local/lib/python3.6/site-packages/flask/app.py", line 1952, in full_dispatch_request
    rv = self.handle_user_exception(e)
  File "/home/ubuntu/.local/lib/python3.6/site-packages/flask/app.py", line 1821, in handle_user_exception
    reraise(exc_type, exc_value, tb)
  File "/home/ubuntu/.local/lib/python3.6/site-packages/flask/_compat.py", line 39, in reraise
    raise value
  File "/home/ubuntu/.local/lib/python3.6/site-packages/flask/app.py", line 1950, in full_dispatch_request
    rv = self.dispatch_request()
  File "/home/ubuntu/.local/lib/python3.6/site-packages/flask/app.py", line 1936, in dispatch_request
    return self.view_functions[rule.endpoint](**req.view_args)
  File "/home/ubuntu/flask_gunicorn_nginx_docker/flask_app/app.py", line 117, in func
    urls = list(data["urls"])
TypeError: 'NoneType' object is not subscriptable
